<?xml version="1.0" encoding="UTF-8"?>
<testsuites name="Mocha Tests" time="0.14900000000000002" tests="7" failures="8">
  <testsuite name="Root Suite" timestamp="2019-08-22T06:06:03" tests="0" failures="1" time="0">
    <testcase name=" Uncaught error outside test suite" time="0" classname="Uncaught error outside test suite">
      <failure message="listen EADDRINUSE: address already in use :::8000" type="Error"><![CDATA[Error: listen EADDRINUSE: address already in use :::8000
    at Server.setupListenHandle [as _listen2] (net.js:1279:14)
    at listenInCluster (net.js:1327:12)
    at Server.listen (net.js:1414:7)
    at Function.listen (node_modules\express\lib\application.js:618:24)
    at Object.<anonymous> (index.js:10:5)
    at Module._compile (internal/modules/cjs/loader.js:778:30)
    at Object.Module._extensions..js (internal/modules/cjs/loader.js:789:10)
    at Module.load (internal/modules/cjs/loader.js:653:32)
    at tryModuleLoad (internal/modules/cjs/loader.js:593:12)
    at Function.Module._load (internal/modules/cjs/loader.js:585:3)
    at Module.require (internal/modules/cjs/loader.js:692:17)
    at require (internal/modules/cjs/helpers.js:25:18)
    at Object.<anonymous> (test\unit\PositionServiceTest.js:5:13)
    at Module._compile (internal/modules/cjs/loader.js:778:30)
    at Object.Module._extensions..js (internal/modules/cjs/loader.js:789:10)
    at Module.load (internal/modules/cjs/loader.js:653:32)
    at tryModuleLoad (internal/modules/cjs/loader.js:593:12)
    at Function.Module._load (internal/modules/cjs/loader.js:585:3)
    at Module.require (internal/modules/cjs/loader.js:692:17)
    at require (internal/modules/cjs/helpers.js:25:18)
    at Array.forEach (<anonymous>)
    at Module._compile (internal/modules/cjs/loader.js:778:30)
    at Object.Module._extensions..js (internal/modules/cjs/loader.js:789:10)
    at Module.load (internal/modules/cjs/loader.js:653:32)
    at tryModuleLoad (internal/modules/cjs/loader.js:593:12)
    at Function.Module._load (internal/modules/cjs/loader.js:585:3)
    at Function.Module.runMain (internal/modules/cjs/loader.js:831:12)
    at startup (internal/bootstrap/node.js:283:19)
    at bootstrapNodeJSCore (internal/bootstrap/node.js:622:3)]]></failure>
    </testcase>
  </testsuite>
  <testsuite name="test" timestamp="2019-08-22T06:06:03" tests="0" file="C:\Users\yuria\Documents\shopper-position-nodejs\test\unit\PositionServiceTest.js" failures="0" time="0">
  </testsuite>
  <testsuite name="healthcheck" timestamp="2019-08-22T06:06:03" tests="1" file="C:\Users\yuria\Documents\shopper-position-nodejs\test\unit\PositionServiceTest.js" failures="1" time="0.031">
    <testcase name="test healthcheck success" time="0.031" classname="success">
      <failure message="Not Found" type="Error"><![CDATA[Error: Not Found
    at Test.Request.callback (node_modules\superagent\lib\node\index.js:626:17)
    at IncomingMessage.<anonymous> (node_modules\superagent\lib\node\index.js:795:18)
    at endReadableNT (_stream_readable.js:1145:12)
    at process._tickCallback (internal/process/next_tick.js:63:19)]]></failure>
    </testcase>
  </testsuite>
  <testsuite name="error handler" timestamp="2019-08-22T06:06:03" tests="3" file="C:\Users\yuria\Documents\shopper-position-nodejs\test\unit\PositionServiceTest.js" failures="3" time="0.09999999999999999">
    <testcase name="test error handler 404" time="0.073" classname="404">
      <failure message="undefined deepEqual 404" type="AssertionError [ERR_ASSERTION]"><![CDATA[AssertionError [ERR_ASSERTION]: undefined deepEqual 404
    at chai.request.post.send.set.then.catch (test\unit\PositionServiceTest.js:39:16)
    at process._tickCallback (internal/process/next_tick.js:68:7)]]></failure>
    </testcase>
    <testcase name="test error handler 400 empty body" time="0.008" classname="400 empty body">
      <failure message="undefined deepEqual 400" type="AssertionError [ERR_ASSERTION]"><![CDATA[AssertionError [ERR_ASSERTION]: undefined deepEqual 400
    at chai.request.post.send.set.then.catch (test\unit\PositionServiceTest.js:48:16)
    at process._tickCallback (internal/process/next_tick.js:68:7)]]></failure>
    </testcase>
    <testcase name="test error handler 400 body error" time="0.019" classname="400 body error">
      <failure message="undefined deepEqual 400" type="AssertionError [ERR_ASSERTION]"><![CDATA[AssertionError [ERR_ASSERTION]: undefined deepEqual 400
    at chai.request.post.send.set.then.catch (test\unit\PositionServiceTest.js:57:16)
    at process._tickCallback (internal/process/next_tick.js:68:7)]]></failure>
    </testcase>
  </testsuite>
  <testsuite name="endpoint" timestamp="2019-08-22T06:06:03" tests="3" file="C:\Users\yuria\Documents\shopper-position-nodejs\test\unit\PositionServiceTest.js" failures="3" time="0.018000000000000002">
    <testcase name="test endpoint 200" time="0.008" classname="200">
      <failure message="Not Found" type="Error"><![CDATA[Error: Not Found
    at Test.Request.callback (node_modules\superagent\lib\node\index.js:626:17)
    at node_modules\superagent\lib\node\index.js:795:18
    at IncomingMessage.<anonymous> (node_modules\superagent\lib\node\parsers\json.js:16:7)
    at endReadableNT (_stream_readable.js:1145:12)
    at process._tickCallback (internal/process/next_tick.js:63:19)]]></failure>
    </testcase>
    <testcase name="test endpoint cache" time="0.005" classname="cache">
      <failure message="Not Found" type="Error"><![CDATA[Error: Not Found
    at Test.Request.callback (node_modules\superagent\lib\node\index.js:626:17)
    at node_modules\superagent\lib\node\index.js:795:18
    at IncomingMessage.<anonymous> (node_modules\superagent\lib\node\parsers\json.js:16:7)
    at endReadableNT (_stream_readable.js:1145:12)
    at process._tickCallback (internal/process/next_tick.js:63:19)]]></failure>
    </testcase>
    <testcase name="test endpoint async save" time="0.005" classname="async save">
      <failure message="Not Found" type="Error"><![CDATA[Error: Not Found
    at Test.Request.callback (node_modules\superagent\lib\node\index.js:626:17)
    at node_modules\superagent\lib\node\index.js:795:18
    at IncomingMessage.<anonymous> (node_modules\superagent\lib\node\parsers\json.js:16:7)
    at endReadableNT (_stream_readable.js:1145:12)
    at process._tickCallback (internal/process/next_tick.js:63:19)]]></failure>
    </testcase>
  </testsuite>
</testsuites>